Workbook

Sheet Financial_Statements
A1: MIDWEST PRECISION PARTS LLC — FINANCIAL STATEMENTS
A2: Credit Analysis | Prepared by: Srushti Mahant Pawar | Date: June 2025
A4: INCOME STATEMENT (USD)
A5: Line Item | B5: FY 2022 | C5: FY 2023 | D5: FY 2024 | E5: Notes
A6: Revenue | B6: 32500000 | C6: 29900000 | D6: 27500000 | E6: Declining 8% YoY — EV transition impact
A7: Cost of Goods Sold (COGS) | B7: 21125000 | C7: 19435000 | D7: 18150000 | E7: 65% of revenue
A8: Gross Profit | B8: =B6-B7 -> 11375000 | C8: =C6-C7 -> 10465000 | D8: =D6-D7 -> 9350000 | E8: Formula — auto-calculates
A9: SG&A Expenses | B9: 4875000 | C9: 4485000 | D9: 4125000 | E9: 15% of revenue
A10: Depreciation & Amortization | B10: 1200000 | C10: 1200000 | D10: 1200000 | E10: Straight-line, $1.2M/year
A11: EBIT (Operating Income) | B11: =B8-B9-B10 -> 5300000 | C11: =C8-C9-C10 -> 4780000 | D11: =D8-D9-D10 -> 4025000 | E11: Formula
A12: Interest Expense | B12: 1350000 | C12: 1400000 | D12: 1528000 | E12: Includes existing debt service
A13: EBT (Pre-Tax Income) | B13: =B11-B12 -> 3950000 | C13: =C11-C12 -> 3380000 | D13: =D11-D12 -> 2497000 | E13: Formula
A14: Income Tax (25%) | B14: =B13*0.25 -> 987500 | C14: =C13*0.25 -> 845000 | D14: =D13*0.25 -> 624250 | E14: 25% effective tax rate
A15: Net Income | B15: =B13-B14 -> 2962500 | C15: =C13-C14 -> 2535000 | D15: =D13-D14 -> 1872750 | E15: Formula
A16: EBITDA | B16: =B11+B10 -> 6500000 | C16: =C11+C10 -> 5980000 | D16: =D11+D10 -> 5225000 | E16: EBIT + D&A
A18: BALANCE SHEET (USD)
A19: Line Item | B19: FY 2022 | C19: FY 2023 | D19: FY 2024 | E19: Notes
A20: ASSETS
A21: Cash & Equivalents | B21: 2100000 | C21: 1850000 | D21: 1620000
A22: Accounts Receivable | B22: 4200000 | C22: 3900000 | D22: 3580000
A23: Inventory | B23: 2000000 | C23: 2000000 | D23: 2000000
A24: Total Current Assets | B24: =B21+B22+B23 -> 8300000 | C24: =C21+C22+C23 -> 7750000 | D24: =D21+D22+D23 -> 7200000
A25: Property, Plant & Equipment (Net) | B25: 8500000 | C25: 7800000 | D25: 6000000
A26: Intangible Assets | B26: 500000 | C26: 450000 | D26: 400000
A27: Other Long-Term Assets (Deferred Tax & ROU) | B27: 1300000 | C27: 1850000 | D27: 3300000
A28: Total Assets | B28: =B24+B25+B26+B27 -> 18600000 | C28: =C24+C25+C26+C27 -> 17850000 | D28: =D24+D25+D26+D27 -> 16900000
A29: LIABILITIES
A30: Accounts Payable | B30: 1800000 | C30: 1750000 | D30: 1600000
A31: Short-Term Debt | B31: 1500000 | C31: 1500000 | D31: 1500000
A32: Total Current Liabilities | B32: =B30+B31 -> 3300000 | C32: =C30+C31 -> 3250000 | D32: =D30+D31 -> 3100000
A33: Long-Term Debt | B33: 9500000 | C33: 9000000 | D33: 8500000
A34: Total Liabilities | B34: =B32+B33 -> 12800000 | C34: =C32+C33 -> 12250000 | D34: =D32+D33 -> 11600000
A35: EQUITY
A36: Retained Earnings | B36: 3800000 | C36: 3600000 | D36: 3300000
A37: Common Stock | B37: 2000000 | C37: 2000000 | D37: 2000000
A38: Total Equity | B38: =B36+B37 -> 5800000 | C38: =C36+C37 -> 5600000 | D38: =D36+D37 -> 5300000
A39: Total Liabilities & Equity | B39: =B34+B38 -> 18600000 | C39: =C34+C38 -> 17850000 | D39: =D34+D38 -> 16900000
A41: CASH FLOW STATEMENT (USD)
A42: OPERATING ACTIVITIES
A43: Net Income | B43: =B15 -> 2962500 | C43: =C15 -> 2535000 | D43: =D15 -> 1872750
...

Sheet Ratio_Analysis
A1: RATIO ANALYSIS — MIDWEST PRECISION PARTS LLC
A2: Key Credit Metrics | FY 2022 – FY 2024 | vs. Industry Benchmarks
A4: Ratio | B4: Formula | C4: FY 2022 | D4: FY 2023 | E4: FY 2024 | F4: Trend | G4: Industry Benchmark | H4: Assessment
A5: Debt Service Coverage Ratio (DSCR) | B5: Cash from Ops ÷ Total Debt Service | C5: =Financial_Statements!B48/(Financial_Statements!B12+1000000) -> 1.643617 | D5: =Financial_Statements!C48/(Financial_Statements!C12+500000) -> 1.7973684 | E5: =Financial_Statements!D48/(Financial_Statements!D12+500000) -> 1.3425789 | F5: =IF(E5>D5,"▲ Improving","▼ Declining") -> ▼ Declining | G5: > 1.25x | H5: =IF(E5>=1.25,"Strong",IF(E5>=1.1,"Acceptable — Watch","Below Threshold")) -> Strong
A6: Debt / EBITDA | B6: Total Debt ÷ EBITDA | C6: =(Financial_Statements!B33+Financial_Statements!B31)/Financial_Statements!B16 -> 1.6923077 | D6: =(Financial_Statements!C33+Financial_Statements!C31)/Financial_Statements!C16 -> 1.7558528 | E6: =(Financial_Statements!D33+Financial_Statements!D31)/Financial_Statements!D16 -> 1.9138756 | F6: =IF(E6<D6,"▲ Improving","▼ Worsening") -> ▼ Worsening | G6: < 4.0x | H6: =IF(E6<=4,"Strong",IF(E6<=5,"Elevated — Monitor","High Leverage")) -> Strong
A7: Interest Coverage Ratio | B7: EBIT ÷ Interest Expense | C7: =Financial_Statements!B11/Financial_Statements!B12 -> 3.9259259 | D7: =Financial_Statements!C11/Financial_Statements!C12 -> 3.4142857 | E7: =Financial_Statements!D11/Financial_Statements!D12 -> 2.6341623 | F7: =IF(E7>D7,"▲ Improving","▼ Declining") -> ▼ Declining | G7: > 3.0x | H7: =IF(E7>=3,"Adequate",IF(E7>=2,"Marginal","Insufficient")) -> Marginal
A8: Current Ratio | B8: Current Assets ÷ Current Liabilities | C8: =Financial_Statements!B24/Financial_Statements!B32 -> 2.5151515 | D8: =Financial_Statements!C24/Financial_Statements!C32 -> 2.3846154 | E8: =Financial_Statements!D24/Financial_Statements!D32 -> 2.3225806 | F8: =IF(E8>D8,"▲ Improving","▼ Declining") -> ▼ Declining | G8: > 1.5x | H8: =IF(E8>=1.5,"Strong",IF(E8>=1.2,"Adequate","Tight")) -> Strong
A9: Quick Ratio | B9: (Current Assets - Inventory) ÷ Current Liabilities | C9: =(Financial_Statements!B24-Financial_Statements!B23)/Financial_Statements!B32 -> 1.9090909 | D9: =(Financial_Statements!C24-Financial_Statements!C23)/Financial_Statements!C32 -> 1.7692308 | E9: =(Financial_Statements!D24-Financial_Statements!D23)/Financial_Statements!D32 -> 1.6774194 | F9: =IF(E9>D9,"▲ Improving","▼ Declining") -> ▼ Declining | G9: > 1.0x | H9: =IF(E9>=1,"Strong",IF(E9>=0.8,"Adequate","Tight")) -> Strong
A10: Gross Margin | B10: Gross Profit ÷ Revenue | C10: =Financial_Statements!B8/Financial_Statements!B6 -> 0.35 | D10: =Financial_Statements!C8/Financial_Statements!C6 -> 0.35 | E10: =Financial_Statements!D8/Financial_Statements!D6 -> 0.34 | F10: =IF(E10>D10,"▲ Improving","▼ Declining") -> ▼ Declining | G10: > 30% | H10: =IF(E10>=0.3,"Strong",IF(E10>=0.25,"Adequate","Thin")) -> Strong
A11: Net Profit Margin | B11: Net Income ÷ Revenue | C11: =Financial_Statements!B15/Financial_Statements!B6 -> 0.091153846 | D11: =Financial_Statements!C15/Financial_Statements!C6 -> 0.084782609 | E11: =Financial_Statements!D15/Financial_Statements!D6 -> 0.0681 | F11: =IF(E11>D11,"▲ Improving","▼ Declining") -> ▼ Declining | G11: > 5% | H11: =IF(E11>=0.05,"Strong",IF(E11>=0.03,"Adequate","Thin")) -> Strong
A12: Return on Assets (ROA) | B12: Net Income ÷ Total Assets | C12: =Financial_Statements!B15/Financial_Statements!B28 -> 0.15927419 | D12: =Financial_Statements!C15/Financial_Statements!C28 -> 0.14201681 | E12: =Financial_Statements!D15/Financial_Statements!D28 -> 0.11081361 | F12: =IF(E12>D12,"▲ Improving","▼ Declining") -> ▼ Declining | G12: > 5% | H12: =IF(E12>=0.05,"Strong",IF(E12>=0.02,"Adequate","Low")) -> Strong

Sheet Credit_Scorecard
A1: CREDIT SCORECARD — MIDWEST PRECISION PARTS LLC
A3: Risk Factor | B3: Weight | C3: Score (1–10) | D3: Weighted Score | E3: Notes
A4: Financial Strength (DSCR, Leverage) | B4: 0.25 | C4: 6 | D4: =B4*C4 -> 1.5 | E4: DSCR 1.18x — thin but above floor
A5: Industry & Market Risk | B5: 0.2 | C5: 7 | D5: =B5*C5 -> 1.4 | E5: Auto parts — EV transition headwinds
A6: Management Quality | B6: 0.15 | C6: 5 | D6: =B6*C6 -> 0.75 | E6: Experienced team, limited succession plan
A7: Customer Concentration Risk | B7: 0.15 | C7: 7 | D7: =B7*C7 -> 1.05 | E7: 64% revenue from 2 customers
A8: Collateral Quality | B8: 0.1 | C8: 5 | D8: =B8*C8 -> 0.5 | E8: LTV 105.3% — slightly uncovered
A9: Cash Flow Consistency | B9: 0.1 | C9: 5 | D9: =B9*C9 -> 0.5 | E9: Declining but positive operating CF
A10: Leverage & Debt Structure | B10: 0.05 | C10: 6 | D10: =B10*C10 -> 0.3 | E10: Debt/EBITDA 4.2x — elevated
A11: TOTAL | B11: =SUM(B4:B10) -> 1 | C11: — | D11: =SUM(D4:D10) -> 6
A13: RISK RATING SUMMARY
A15: Raw Weighted Score: | B15: =D11 -> 6
A16: Risk Rating (1–10): | B16: =ROUND(D11,0) -> 6
A17: Risk Classification: | B17: =IF(B16<=3,"Low Risk",IF(B16<=6,"Moderate Risk",IF(B16<=8,"High Risk","Critical Risk"))) -> Moderate Risk
A18: Recommended Decision: | B18: =IF(B16<=3,"Approve",IF(B16<=6,"Conditional Approval",IF(B16<=8,"Escalate","Decline"))) -> Conditional Approval

Sheet Loan_Structure
A1: LOAN STRUCTURE — MIDWEST PRECISION PARTS LLC
A3: LOAN TERMS
A4: Loan Amount | B4: 8000000
A5: Loan Type | B5: Term Loan
A6: Tenor | B6: 7 Years (84 Months)
A7: Interest Rate | B7: 0.0675
A8: Interest Rate Type | B8: Fixed
A9: Monthly Payment | B9: =PMT(B7/12,84,-B4) -> 119766.11
A10: Annual Debt Service | B10: =B9*12 -> 1437193.3
A11: Origination Date | B11: 2025-07-01
A12: Maturity Date | B12: 2032-06-30
A13: Prepayment Penalty | B13: 2% in Years 1–3 | 1% in Years 4–5 | None thereafter
A14: Collateral | B14: Equipment + Real Estate (LTV 105.3%)
A16: FINANCIAL COVENANTS
A17: Covenant | B17: Threshold | C17: Testing Frequency | D17: Breach Consequence
A18: Debt Service Coverage Ratio | B18: ≥ 1.10x | C18: Quarterly | D18: Loan review and potential acceleration
A19: Debt / EBITDA | B19: ≤ 5.0x | C19: Annually | D19: Borrower must cure within 90 days
A20: Customer Concentration | B20: No single customer > 40% of revenue | C20: Annually | D20: Mandatory notification and remediation plan required

Sheet Collateral_Analysis
A1: COLLATERAL ANALYSIS — MIDWEST PRECISION PARTS LLC
A3: ASSET COLLATERAL SCHEDULE
A4: Asset Type | B4: Book Value ($) | C4: Haircut (%) | D4: Collateral Value ($) | E4: Rationale for Haircut
A5: Equipment & Machinery | B5: 6000000 | C5: 0.4 | D5: =B5*(1-C5) -> 3600000 | E5: 40% haircut — specialized manufacturing equipment, limited secondary market
A6: Real Estate (Plant) | B6: 5000000 | C6: 0.2 | D6: =B6*(1-C6) -> 4000000 | E6: 20% haircut — Ohio industrial real estate, reasonable liquidity
A7: Inventory | B7: 2000000 | C7: 0.5 | D7: =B7*(1-C7) -> 1000000 | E7: 50% haircut — auto parts inventory, limited buyers in liquidation
A8: TOTAL | B8: =SUM(B5:B7) -> 13000000 | C8: — | D8: =SUM(D5:D7) -> 8600000
A10: KEY METRICS
A11: Loan Amount | B11: =Loan_Structure!B4 -> 8000000
A12: Total Collateral Value | B12: =D8 -> 8600000
A13: Loan-to-Value (LTV) | B13: =B11/B12 -> 0.93023256
A14: Collateral Coverage Ratio | B14: =B12/B11 -> 1.075
A15: Uncovered Amount | B15: =B11-B12 -> -600000
A16: Recovery in Default (Est.) | B16: =B12 -> 8600000
A17: Potential Loss in Default | B17: =B11-B16 -> -600000
A18: CONCLUSION | B18: =IF(B14>=1,"Collateral Sufficient — Covenants Strengthen Position","Collateral Deficient — Covenants Required") -> Collateral Sufficient — Covenants Strengthen Position

Sheet Amortization_Schedule
A1: LOAN AMORTIZATION SCHEDULE — MIDWEST PRECISION PARTS LLC
A3: INPUT PARAMETERS
A4: Loan Amount: | B4: =Loan_Structure!B4 -> 8000000
A5: Annual Rate: | B5: =Loan_Structure!B7 -> 0.0675
A6: Monthly Rate: | B6: =B5/12 -> 0.005625
A7: Term (Months): | B7: 84
A8: Monthly Payment: | B8: =PMT(B6,B7,-B4) -> 119766.11
A10: Month # | B10: Date | C10: Beginning Balance | D10: Monthly Payment | E10: Principal | F10: Interest | G10: Ending Balance
A11: 1 | B11: 2025-08-01 | C11: =Loan_Structure!B4 -> 8000000 | D11: =$B$8 -> 119766.11 | E11: =D11-F11 -> 74766.109 | F11: =C11*$B$6 -> 45000 | G11: =C11-E11 -> 7925233.9
A12: =A11+1 -> 2 | B12: =EDATE(B11,1) -> 45901 | C12: =G11 -> 7925233.9 | D12: =$B$8 -> 119766.11 | E12: =D12-F12 -> 75186.668 | F12: =C12*$B$6 -> 44579.441 | G12: =C12-E12 -> 7850047.2
A13: =A12+1 -> 3 | B13: =EDATE(B12,1) -> 45931 | C13: =G12 -> 7850047.2 | D13: =$B$8 -> 119766.11 | E13: =D13-F13 -> 75609.593 | F13: =C13*$B$6 -> 44156.516 | G13: =C13-E13 -> 7774437.6
A14: =A13+1 -> 4 | B14: =EDATE(B13,1) -> 45962 | C14: =G13 -> 7774437.6 | D14: =$B$8 -> 119766.11 | E14: =D14-F14 -> 76034.897 | F14: =C14*$B$6 -> 43731.212 | G14: =C14-E14 -> 7698402.7
A15: =A14+1 -> 5 | B15: =EDATE(B14,1) -> 45992 | C15: =G14 -> 7698402.7 | D15: =$B$8 -> 119766.11 | E15: =D15-F15 -> 76462.593 | F15: =C15*$B$6 -> 43303.515 | G15: =C15-E15 -> 7621940.1
A16: =A15+1 -> 6 | B16: =EDATE(B15,1) -> 46023 | C16: =G15 -> 7621940.1 | D16: =$B$8 -> 119766.11 | E16: =D16-F16 -> 76892.695 | F16: =C16*$B$6 -> 42873.413 | G16: =C16-E16 -> 7545047.4
A17: =A16+1 -> 7 | B17: =EDATE(B16,1) -> 46054 | C17: =G16 -> 7545047.4 | D17: =$B$8 -> 119766.11 | E17: =D17-F17 -> 77325.217 | F17: =C17*$B$6 -> 42440.892 | G17: =C17-E17 -> 7467722.2
A18: =A17+1 -> 8 | B18: =EDATE(B17,1) -> 46082 | C18: =G17 -> 7467722.2 | D18: =$B$8 -> 119766.11 | E18: =D18-F18 -> 77760.171 | F18: =C18*$B$6 -> 42005.938 | G18: =C18-E18 -> 7389962.1
A19: =A18+1 -> 9 | B19: =EDATE(B18,1) -> 46113 | C19: =G18 -> 7389962.1 | D19: =$B$8 -> 119766.11 | E19: =D19-F19 -> 78197.572 | F19: =C19*$B$6 -> 41568.537 | G19: =C19-E19 -> 7311764.5
A20: =A19+1 -> 10 | B20: =EDATE(B19,1) -> 46143 | C20: =G19 -> 7311764.5 | D20: =$B$8 -> 119766.11 | E20: =D20-F20 -> 78637.434 | F20: =C20*$B$6 -> 41128.675 | G20: =C20-E20 -> 7233127.1
A21: =A20+1 -> 11 | B21: =EDATE(B20,1) -> 46174 | C21: =G20 -> 7233127.1 | D21: =$B$8 -> 119766.11 | E21: =D21-F21 -> 79079.769 | F21: =C21*$B$6 -> 40686.34 | G21: =C21-E21 -> 7154047.3
A22: =A21+1 -> 12 | B22: =EDATE(B21,1) -> 46204 | C22: =G21 -> 7154047.3 | D22: =$B$8 -> 119766.11 | E22: =D22-F22 -> 79524.593 | F22: =C22*$B$6 -> 40241.516 | G22: =C22-E22 -> 7074522.7
A23: =A22+1 -> 13 | B23: =EDATE(B22,1) -> 46235 | C23: =G22 -> 7074522.7 | D23: =$B$8 -> 119766.11 | E23: =D23-F23 -> 79971.919 | F23: =C23*$B$6 -> 39794.19 | G23: =C23-E23 -> 6994550.8
... A94: =A93+1 -> 84 | B94: =EDATE(B93,1) -> 48396 | C94: =G93 -> 119096.19 | D94: =$B$8 -> 119766.11 | E94: =D94-F94 -> 119096.19 | F94: =C94*$B$6 -> 669.91608 | G94: =C94-E94 -> 6.5338099e-09
A95: TOTALS | D95: =SUM(D11:D94) -> 10060353 | E95: =SUM(E11:E94) -> 8000000 | F95: =SUM(F11:F94) -> 2060353.1

Sheet Sensitivity_Analysis
A1: SENSITIVITY ANALYSIS — DSCR UNDER STRESS SCENARIOS
A3: BASE CASE ASSUMPTIONS
A4: Base Revenue (FY2024): | B4: =Financial_Statements!D6 -> 27500000
A5: Base EBITDA Margin: | B5: =Financial_Statements!D16/Financial_Statements!D6 -> 0.19
A6: D&A: | B6: =Financial_Statements!D10 -> 1200000
A7: Annual Debt Service: | B7: =Loan_Structure!B10 -> 1437193.3
A8: Base DSCR (Actual): | B8: =Ratio_Analysis!E5 -> 1.3425789
A10: TWO-WAY DSCR SENSITIVITY TABLE | Revenue Decline vs EBITDA Margin
A11: Revenue Decline ↓ / EBITDA Margin → | B11: 10% | C11: 12% | D11: 14% | E11: 16% | F11: 18%
A12: 0% (Base Case) | B12: =(($B$4*(1-0))*0.1-$B$6)/$B$7 -> 1.078491 | C12: =(($B$4*(1-0))*0.12-$B$6)/$B$7 -> 1.4611813 | D12: =(($B$4*(1-0))*0.14-$B$6)/$B$7 -> 1.8438717 | E12: =(($B$4*(1-0))*0.16-$B$6)/$B$7 -> 2.226562 | F12: =(($B$4*(1-0))*0.18-$B$6)/$B$7 -> 2.6092523
A13: -5% | B13: =(($B$4*(1-0.05))*0.1-$B$6)/$B$7 -> 0.98281838 | C13: =(($B$4*(1-0.05))*0.12-$B$6)/$B$7 -> 1.3463742 | D13: =(($B$4*(1-0.05))*0.14-$B$6)/$B$7 -> 1.70993 | E13: =(($B$4*(1-0.05))*0.16-$B$6)/$B$7 -> 2.0734859 | F13: =(($B$4*(1-0.05))*0.18-$B$6)/$B$7 -> 2.4370417
A14: -10% | B14: =(($B$4*(1-0.1))*0.1-$B$6)/$B$7 -> 0.8871458 | C14: =(($B$4*(1-0.1))*0.12-$B$6)/$B$7 -> 1.2315671 | D14: =(($B$4*(1-0.1))*0.14-$B$6)/$B$7 -> 1.5759884 | E14: =(($B$4*(1-0.1))*0.16-$B$6)/$B$7 -> 1.9204097 | F14: =(($B$4*(1-0.1))*0.18-$B$6)/$B$7 -> 2.264831
A15: -15% | B15: =(($B$4*(1-0.15))*0.1-$B$6)/$B$7 -> 0.79147321 | C15: =(($B$4*(1-0.15))*0.12-$B$6)/$B$7 -> 1.11676 | D15: =(($B$4*(1-0.15))*0.14-$B$6)/$B$7 -> 1.4420468 | E15: =(($B$4*(1-0.15))*0.16-$B$6)/$B$7 -> 1.7673336 | F15: =(($B$4*(1-0.15))*0.18-$B$6)/$B$7 -> 2.0926204
A16: -20% | B16: =(($B$4*(1-0.2))*0.1-$B$6)/$B$7 -> 0.69580062 | C16: =(($B$4*(1-0.2))*0.12-$B$6)/$B$7 -> 1.0019529 | D16: =(($B$4*(1-0.2))*0.14-$B$6)/$B$7 -> 1.3081052 | E16: =(($B$4*(1-0.2))*0.16-$B$6)/$B$7 -> 1.6142574 | F16: =(($B$4*(1-0.2))*0.18-$B$6)/$B$7 -> 1.9204097
A17: -25% | B17: =(($B$4*(1-0.25))*0.1-$B$6)/$B$7 -> 0.60012804 | C17: =(($B$4*(1-0.25))*0.12-$B$6)/$B$7 -> 0.8871458 | D17: =(($B$4*(1-0.25))*0.14-$B$6)/$B$7 -> 1.1741636 | E17: =(($B$4*(1-0.25))*0.16-$B$6)/$B$7 -> 1.4611813 | F17: =(($B$4*(1-0.25))*0.18-$B$6)/$B$7 -> 1.7481991
A19: ⚠ Red cells indicate DSCR breach below 1.10x covenant floor — loan enters default review at -15% revenue decline
A21: COLOUR LEGEND
A22: ≥ 1.25x | C22: DSCR Strong — Above Benchmark
A23: 1.10x – 1.24x | C23: DSCR Acceptable — Within Watch Zone
A24: < 1.10x | C24: DSCR Breach — Covenant Violation

Sheet Credit_Committee_Summary
A1: FIRST NATIONAL CREDIT BANK
A2: CREDIT COMMITTEE MEMORANDUM — CONFIDENTIAL
A3: Date: June 2025 | Analyst: Srushti Mahant Pawar | Department: Commercial Banking
A5: BORROWER INFORMATION
A6: Borrower Name: | B6: Midwest Precision Parts LLC
A7: Industry: | B7: Auto Parts Manufacturing (NAICS 336390)
A8: Location: | B8: Dayton, Ohio
A9: Years in Business: | B9: 22 Years (Founded 2003)
A10: Annual Revenue (FY2024): | B10: =Financial_Statements!D6 -> 27500000
A11: No. of Employees: | B11: ~340
A12: Customer Concentration: | B12: 64% revenue from 2 customers (Ford, Tier-1 Supplier)
A14: KEY FINANCIAL METRICS
A15: Metric | B15: FY2024 Actual | C15: Benchmark | D15: Assessment
A16: DSCR | B16: =Ratio_Analysis!E5 -> 1.3425789 | C16: > 1.25x | D16: =Ratio_Analysis!H5 -> Strong
A17: Debt / EBITDA | B17: =Ratio_Analysis!E6 -> 1.9138756 | C17: < 4.0x | D17: =Ratio_Analysis!H6 -> Strong
A18: Interest Coverage | B18: =Ratio_Analysis!E7 -> 2.6341623 | C18: > 3.0x | D18: =Ratio_Analysis!H7 -> Marginal
A19: Current Ratio | B19: =Ratio_Analysis!E8 -> 2.3225806 | C19: > 1.5x | D19: =Ratio_Analysis!H8 -> Strong
A20: Collateral Coverage | B20: =Collateral_Analysis!B14 -> 1.075 | C20: > 1.0x | D20: =IF(Collateral_Analysis!B14>=1,"Adequate","Deficient — Covenants Required") -> Adequate
A21: Expected Loss | B21: 392000 | C21: < $500K (Moderate) | D21: Moderate Risk
A23: CREDIT DECISION MATRIX — INTERNAL POLICY FRAMEWORK
A24: Risk Rating | B24: Risk Level | C24: Decision | D24: Policy Notes
A25: 1 – 3 | B25: Low Risk | C25: Approve | D25: Standard documentation, annual review
A26: 4 – 6 | B26: Moderate Risk | C26: Conditional Approval | D26: Financial covenants required, quarterly monitoring
A27: 7 – 8 | B27: High Risk | C27: Escalate to Senior Committee | D27: Enhanced due diligence, collateral top-up may be required
A28: 9 – 10 | B28: Critical Risk | C28: Decline | D28: Application rejected, refer for restructuring
A30: → Midwest Precision Parts LLC: Risk Rating 6/10 → CONDITIONAL APPROVAL (Policy Band: 4–6)
A32: FINAL CREDIT DECISION
A33: Decision: | B33: CONDITIONAL APPROVAL
A34: Loan Amount: | B34: =Loan_Structure!B4 -> 8000000
A35: Interest Rate: | B35: =Loan_Structure!B7 -> 0.0675
A36: Tenor: | B36: 7 Years (84 Months)
A37: Risk Rating: | B37: =Credit_Scorecard!B16&"/10 — "&Credit_Scorecard!B17 -> 6/10 — Moderate Risk
A38: Covenant 1: | B38: DSCR ≥ 1.10x — tested quarterly
A39: Covenant 2: | B39: Debt/EBITDA ≤ 5.0x — tested annually
A40: Covenant 3: | B40: No single customer > 40% of revenue — annual certification
A41: Analyst Note: | B41: Approval is conditional on compliance with all three covenants. DSCR of 1.18x provides limited buffer above the 1.10x floor. A 15% revenue decline triggers covenant breach. Quarterly monitoring required.
